Workbook

Sheet รายชื่อโรงสี
A1: ลำดับ | B1: ชื่อโรงสี | C1: ประเภท | D1: กำลังการผลิต (ตัน/วัน) | E1: จังหวัด | F1: อำเภอ | G1: ตำบล | H1: ที่อยู่ | I1: รหัสไปรษณีย์ | J1: โทรศัพท์ | K1: Latitude | L1: Longitude | M1: ที่มาพิกัด
A2: 1 | B2: บริษัท บีบีพี โปรดิวซ์ จำกัด | C2: โรงสีขนาดกลาง | D2: 200 | E2: กรุงเทพมหานคร | F2: บางคอแหลม | G2: บางโคล่ | H2: เลขที่ 697/15-20 ถนน ตรอกวัดจันทร์ใน แขวงบางโคล่ เขตบางคอแหลม กรุงเทพมหานคร 10120 | I2: 10120 | K2: 13.692452 | L2: 100.51401 | M2: OSM Nominatim — ระดับตำบล
A3: 2 | B3: บริษัท บางซื่อโรงสีไฟเจียเม้ง จำกัด | C3: โรงสีขนาดใหญ่ | D3: 436 | E3: กรุงเทพมหานคร | F3: บางซื่อ | G3: บางซื่อ | H3: เลขที่ 102 ซอย ซอยริมทางรถไฟบางซื่อ แขวงบางซื่อ เขตบางซื่อ กรุงเทพมหานคร 10800 | I3: 10800 | J3: 028322834 | K3: 13.809713 | L3: 100.53744 | M3: OSM Nominatim — ระดับตำบล
A4: 3 | B4: บริษัท บางซื่อโรงสีไฟเจียเม้ง จำกัด | C4: โรงสีขนาดใหญ่ | D4: 400 | E4: กรุงเทพมหานคร | F4: บางซื่อ | G4: บางซื่อ | H4: เลขที่ 102 ซอย ซอยริมทางรถไฟบางซื่อ แขวงบางซื่อ เขตบางซื่อ กรุงเทพมหานคร 10800 | I4: 10800 | J4: 028322834 | K4: 13.809713 | L4: 100.53744 | M4: OSM Nominatim — ระดับตำบล
A5: 4 | B5: บริษัท บางซื่อโรงสีไฟเจียเม้ง จำกัด | C5: โรงสีขนาดใหญ่ | D5: 800 | E5: กรุงเทพมหานคร | F5: บางซื่อ | G5: บางซื่อ | H5: เลขที่ 102 ซอย ซอยริมทางรถไฟบางซื่อ แขวงบางซื่อ เขตบางซื่อ กรุงเทพมหานคร 10800 | I5: 10800 | J5: 028322834 | K5: 13.809713 | L5: 100.53744 | M5: OSM Nominatim — ระดับตำบล
A6: 5 | B6: บริษัท บางซื่อโรงสีไฟเจียเม้ง จำกัด | C6: โรงสีขนาดใหญ่ | D6: 720 | E6: กรุงเทพมหานคร | F6: บางซื่อ | G6: บางซื่อ | H6: เลขที่ 102 ซอย ซอยริมทางรถไฟบางซื่อ แขวงบางซื่อ เขตบางซื่อ กรุงเทพมหานคร 10800 | I6: 10800 | J6: 028322834 | K6: 13.809713 | L6: 100.53744 | M6: OSM Nominatim — ระดับตำบล
A7: 6 | B7: บริษัท ข้าว ซี.พี. จำกัด | C7: โรงสีขนาดใหญ่ | D7: 400 | E7: กรุงเทพมหานคร | F7: บางรัก | G7: สีลม | H7: เลขที่ 313 ถนน สีลม แขวงสีลม เขตบางรัก กรุงเทพมหานคร 10500 | I7: 10500 | J7: 02-6467357 | K7: 13.726234 | L7: 100.52813 | M7: OSM Nominatim — ระดับตำบล
A8: 7 | B8: บริษัท ข้าว ซี.พี. จำกัด | C8: โรงสีขนาดใหญ่ | D8: 400 | E8: กรุงเทพมหานคร | F8: บางรัก | G8: สีลม | H8: เลขที่ 313 ถนน สีลม แขวงสีลม เขตบางรัก กรุงเทพมหานคร 10500 | I8: 10500 | J8: 02-6467357 | K8: 13.726234 | L8: 100.52813 | M8: OSM Nominatim — ระดับตำบล
A9: 8 | B9: บริษัท ข้าว ซี.พี. จำกัด | C9: โรงสีขนาดกลาง | D9: 96 | E9: กรุงเทพมหานคร | F9: บางรัก | G9: สีลม | H9: เลขที่ 313 ถนน สีลม แขวงสีลม เขตบางรัก กรุงเทพมหานคร 10500 | I9: 10500 | J9: 02-6467357 | K9: 13.726234 | L9: 100.52813 | M9: OSM Nominatim — ระดับตำบล
A10: 9 | B10: บริษัท ไร้ซ์แลนด์ อินเตอร์เนชั่นแนล จำกัด | C10: โรงสีขนาดใหญ่ | D10: 500 | E10: กรุงเทพมหานคร | F10: บางรัก | G10: สุริยวงศ์ | H10: เลขที่ 38/17 ซอย อนุมานราชธน ถนน เดโช แขวงสุริยวงศ์ เขตบางรัก กรุงเทพมหานคร 10500 | I10: 10500 | J10: 02-3393031 | K10: 13.726431 | L10: 100.52415 | M10: OSM Nominatim — ระดับตำบล
A11: 10 | B11: บริษัท พีทีเคเทรดเดอร์ จำกัด | C11: โรงสีขนาดใหญ่ | D11: 600 | E11: กรุงเทพมหานคร | F11: บึงกุ่ม | G11: นวลจันทร์ | H11: เลขที่ 55/237 ถนน คลองลำเจียก แขวงนวลจันทร์ เขตบึงกุ่ม กรุงเทพมหานคร 10230 | I11: 10230 | J11: 0919156462 | K11: 13.834879 | L11: 100.63771 | M11: OSM Nominatim — ระดับตำบล
A12: 11 | B12: บริษัท ชัยประสิทธิ์พืชผล จำกัด | C12: โรงสีขนาดกลาง | D12: 90 | E12: กรุงเทพมหานคร | F12: ป้อมปราบศัตรูพ่าย | G12: วัดเทพศิรินทร์ | H12: เลขที่ 678/4-7 ถนน บำรุงเมือง แขวงวัดเทพศิรินทร์ เขตป้อมปราบศัตรูพ่าย กรุงเทพมหานคร 10100 | I12: 10100 | J12: 089-1299990 | K12: 13.746956 | L12: 100.51433 | M12: OSM Nominatim — ระดับตำบล
A13: 12 | B13: ห้างหุ้นส่วนจำกัด โรงสีไฟศรีกรุงลาดกระบัง | C13: โรงสีขนาดใหญ่ | D13: 400 | E13: กรุงเทพมหานคร | F13: ลาดกระบัง | G13: ทับยาว | H13: เลขที่ 34/1 ถนน ถ.ประชาพัฒนา แขวงทับยาว เขตลาดกระบัง กรุงเทพมหานคร 10520 | I13: 10520 | J13: 02-1729745-6 | K13: 13.732507 | L13: 100.83634 | M13: OSM Nominatim — ระดับตำบล
A14: 13 | B14: บริษัท เจริญโภคภัณฑ์โปรดิ๊วส จำกัด | C14: โรงสีขนาดใหญ่ | D14: 1000 | E14: กรุงเทพมหานคร | F14: สาทร | G14: ทุ่งวัดดอน | H14: เลขที่ 97 ถนน เย็นจิต แขวงทุ่งวัดดอน เขตสาทร กรุงเทพมหานคร 10120 | I14: 10120 | K14: 13.712446 | L14: 100.52144 | M14: OSM Nominatim — ระดับตำบล
A15: 14 | B15: บริษัท พิมานวรกิจ 1999 จำกัด | C15: โรงสีขนาดใหญ่ | D15: 430 | E15: กรุงเทพมหานคร | F15: หนองจอก | G15: กระทุ่มราย | H15: เลขที่ 15-15/1 ถนน ถ.สังฆสันติสุข แขวงกระทุ่มราย เขตหนองจอก กรุงเทพมหานคร 10530 | I15: 10530 | J15: 02-9883339 | K15: 13.811743 | L15: 100.93165 | M15: OSM Nominatim — ระดับตำบล
A16: 15 | B16: บริษัท มหานครธัญกิจ จำกัด | C16: โรงสีขนาดกลาง | D16: 130 | E16: กรุงเทพมหานคร | F16: หนองจอก | G16: ลำผักชี | H16: เลขที่ 85 หมู่ 9 ถนน ถ.สุวินทวงศ์ แขวงลำผักชี เขตหนองจอก กรุงเทพมหานคร 10530 | I16: 10530 | J16: 02-9884700 | K16: 13.784278 | L16: 100.8285 | M16: OSM Nominatim — ระดับตำบล
A17: 16 | B17: บริษัท เกษตรโชคชัยการเกษตร จำกัด | C17: โรงสีขนาดใหญ่ | D17: 430 | E17: กรุงเทพมหานคร | F17: หนองจอก | G17: กระทุ่มราย | H17: เลขที่ 30/6 ถนน ถ.สังฆสันติสุข แขวงกระทุ่มราย เขตหนองจอก กรุงเทพมหานคร 10530 | I17: 10530 | J17: 02-9882095-7 | K17: 13.811743 | L17: 100.93165 | M17: OSM Nominatim — ระดับตำบล
A18: 17 | B18: บริษัท เม้งไต๋ ไรซ์ จำกัด | C18: โรงสีขนาดใหญ่ | D18: 1500 | E18: กรุงเทพมหานคร | F18: ห้วยขวาง | G18: ห้วยขวาง | H18: เลขที่ 184/164 ถนน รัชดาภิเษก แขวงห้วยขวาง เขตห้วยขวาง กรุงเทพมหานคร 10310 | I18: 10310 | J18: 02-2749911-15 | K18: 13.778568 | L18: 100.5746 | M18: OSM Nominatim — ระดับตำบล
A19: 18 | B19: บริษัท เหล่าบัณฑิต ไรซ์ จำกัด | C19: โรงสีขนาดใหญ่ | D19: 500 | E19: กรุงเทพมหานคร | F19: ห้วยขวาง | G19: สามเสนนอก | H19: เลขที่ 296/4 หมู่ - แขวงสามเสนนอก เขตห้วยขวาง กรุงเทพมหานคร 10310 | I19: 10310 | J19: 0819067080 | K19: 13.769315 | L19: 100.58975 | M19: OSM Nominatim — ระดับตำบล
A20: 19 | B20: บริษัท เอ็มที เซ็นเตอร์เทรด จำกัด | C20: โรงสีขนาดใหญ่ | D20: 2000 | E20: กรุงเทพมหานคร | F20: ห้วยขวาง | G20: ห้วยขวาง | H20: เลขที่ 184/165 อาคาร อาคารฟอรั่มทาวเวอร์ ชั้น 26 ถนน ถ.รัชดาภิเษก แขวงห้วยขวาง เขตห้วยขวาง กรุงเทพมหานคร 10400 | I20: 10400 | J20: 02-2749911-15 | K20: 13.778568 | L20: 100.5746 | M20: OSM Nominatim — ระดับตำบล
A21: 20 | B21: บริษัท ข้าวนครกาญจน์ จำกัด | C21: โรงสีขนาดใหญ่ | D21: 350 | E21: กาญจนบุรี | F21: ท่ามะกา | G21: ตะคร้ำเอน | H21: เลขที่ 9 หมู่ 9 ตำบลตะคร้ำเอน อำเภอท่ามะกา จังหวัดกาญจนบุรี 71130 | I21: 71130 | J21: 099-4451939 | K21: 13.989491 | L21: 99.768823 | M21: OSM Nominatim — ระดับตำบล
A22: 21 | B22: โรงสีชัยประเสริฐ | C22: โรงสีขนาดเล็ก | D22: 10 | E22: กาญจนบุรี | F22: ท่ามะกา | G22: ท่าไม้ | H22: เลขที่ 103 หมู่ 2 ถนน - ตำบลท่าไม้ อำเภอท่ามะกา จังหวัดกาญจนบุรี 71120 | I22: 71120 | K22: 13.886985 | L22: 99.802476 | M22: OSM Nominatim — ระดับตำบล
A23: 22 | B23: บริษัท โรงสีแสงศักดิ์ จำกัด | C23: โรงสีขนาดกลาง | D23: 70 | E23: กาญจนบุรี | F23: ท่าม่วง | G23: บ้านใหม่ | H23: เลขที่ 95/1 หมู่ 3 ตำบลบ้านใหม่ อำเภอท่าม่วง จังหวัดกาญจนบุรี 71110 | I23: 71110 | J23: 034658058 | K23: 13.930349 | L23: 99.643443 | M23: OSM Nominatim — ระดับอำเภอ (ตำบลหาไม่เจอ)
A24: 23 | B24: ห้างหุ้นส่วนจำกัด โรงสีรังสรรค์พืชผล | C24: โรงสีขนาดกลาง | D24: 300 | E24: กาญจนบุรี | F24: ท่าม่วง | G24: ทุ่งทอง | H24: เลขที่ 2 หมู่ 4 ตำบลทุ่งทอง อำเภอท่าม่วง จังหวัดกาญจนบุรี 71110 | I24: 71110 | J24: 034510752 | K24: 13.930349 | L24: 99.643443 | M24: OSM Nominatim — ระดับอำเภอ (ตำบลหาไม่เจอ)
A25: 24 | B25: โรงสีการพานิช | C25: โรงสีขนาดกลาง | D25: 200 | E25: กาญจนบุรี | F25: ท่าม่วง | G25: พังตรุ | H25: เลขที่ 9/2 หมู่ 2 ตำบลพังตรุ อำเภอท่าม่วง จังหวัดกาญจนบุรี 71110 | I25: 71110 | J25: 0816413553 | K25: 13.930349 | L25: 99.643443 | M25: OSM Nominatim — ระดับอำเภอ (ตำบลหาไม่เจอ)
A26: 25 | B26: โรงสีตวงสุวรรณ | C26: โรงสีขนาดกลาง | D26: 80 | E26: กาญจนบุรี | F26: ท่าม่วง | G26: ท่าล้อ | H26: เลขที่ 98 หมู่ 1 ถนน แสงชูโต ตำบลท่าล้อ อำเภอท่าม่วง จังหวัดกาญจนบุรี 71000 | I26: 71000 | J26: 034-604480 | K26: 14.004146 | L26: 99.549034 | M26: OSM Nominatim — ระดับตำบล
A27: 26 | B27: โรงสีโชคกิตติพาณิชย์ | C27: โรงสีขนาดกลาง | D27: 80 | E27: กาญจนบุรี | F27: ท่าม่วง | G27: หนองขาว | H27: เลขที่ 185/48 หมู่ 4 ถนน ท่าม่วง-หนองขาว ตำบลหนองขาว อำเภอท่าม่วง จังหวัดกาญจนบุรี 71110 | I27: 71110 | K27: 14.02849 | L27: 99.621343 | M27: OSM Nominatim — ระดับตำบล
A28: 27 | B28: ธนพสิษฐ์ พูนทรัพย์ | C28: โรงสีขนาดเล็ก | D28: 25 | E28: กาญจนบุรี | F28: พนมทวน | G28: รางหวาย | H28: เลขที่ 139 หมู่ 18 ถนน - ตำบลรางหวาย อำเภอพนมทวน จังหวัดกาญจนบุรี 71170 | I28: 71170 | K28: 14.254942 | L28: 99.821101 | M28: OSM Nominatim — ระดับตำบล
A29: 28 | B29: บริษัท กาญจน์ธัญญะชาติ จำกัด | C29: โรงสีขนาดใหญ่ | D29: 1000 | E29: กาญจนบุรี | F29: พนมทวน | G29: หนองสาหร่าย | H29: เลขที่ 66 หมู่ 6 ตำบลหนองสาหร่าย อำเภอพนมทวน จังหวัดกาญจนบุรี 71140 | I29: 71140 | J29: 0922523866 | K29: 14.129361 | L29: 99.69982 | M29: OSM Nominatim — ระดับตำบล
A30: 29 | B30: บริษัท กิจเจริญชัย รุ่งเรือง จำกัด | C30: โรงสีขนาดใหญ่ | D30: 400 | E30: กาญจนบุรี | F30: พนมทวน | G30: หนองโรง | H30: เลขที่ 94 หมู่ 2 ตำบลหนองโรง อำเภอพนมทวน จังหวัดกาญจนบุรี 71120 | I30: 71120 | J30: 087112888 | K30: 14.147976 | L30: 99.676776 | M30: OSM Nominatim — ระดับอำเภอ (ตำบลหาไม่เจอ)
A31: 30 | B31: สมอสีข้าว | C31: โรงสีขนาดเล็ก | D31: 16 | E31: กาญจนบุรี | F31: พนมทวน | G31: ทุ่งสมอ | H31: เลขที่ 150 หมู่ 1 ถนน กาญจนบุรี-อู่ทอง ตำบลทุ่งสมอ อำเภอพนมทวน จังหวัดกาญจนบุรี 71140 | I31: 71140 | K31: 14.147976 | L31: 99.676776 | M31: OSM Nominatim — ระดับอำเภอ (ตำบลหาไม่เจอ)
A32: 31 | B32: บริษัท เต็กรุ่งเรืองไรซ์มิลล์ จำกัด | C32: โรงสีขนาดกลาง | D32: 200 | E32: กาญจนบุรี | F32: ห้วยกระเจา | G32: ดอนแสลบ | H32: เลขที่ 287/1 หมู่ 10 ตำบลดอนแสลบ อำเภอห้วยกระเจา จังหวัดกาญจนบุรี 71170 | I32: 71170 | J32: 0909073986 | K32: 14.350869 | L32: 99.688049 | M32: OSM Nominatim — ระดับอำเภอ (ตำบลหาไม่เจอ)
A33: 32 | B33: บริษัท สมบัติเพิ่มผล จำกัด | C33: โรงสีขนาดกลาง | D33: 120 | E33: กาญจนบุรี | F33: เมืองกาญจนบุรี | G33: หนองบัว | H33: เลขที่ 95/1 หมู่ 4 ถนน - ตำบลหนองบัว อำเภอเมืองกาญจนบุรี จังหวัดกาญจนบุรี 71190 | I33: 71190 | J33: 089-0034514 | K33: 14.060466 | L33: 99.447366 | M33: OSM Nominatim — ระดับตำบล
A34: 33 | B34: นายปรีชา น้าประเสริฐ | C34: โรงสีขนาดเล็ก | D34: 16 | E34: กาญจนบุรี | F34: เลาขวัญ | G34: หนองปลิง | H34: เลขที่ 41 หมู่ 11 ถนน - ตำบลหนองปลิง อำเภอเลาขวัญ จังหวัดกาญจนบุรี 71210 | I34: 71210 | K34: 14.591952 | L34: 99.691822 | M34: OSM Nominatim — ระดับอำเภอ (ตำบลหาไม่เจอ)
A35: 34 | B35: ภูรุ่งเรืองทรัพย์ | C35: โรงสีขนาดเล็ก | D35: 15 | E35: กาฬสินธุ์ | F35: กมลาไสย | G35: กมลาไสย | H35: เลขที่ 90 หมู่ 10 ถนน - ตำบลกมลาไสย อำเภอกมลาไสย จังหวัดกาฬสินธุ์ 46130 | I35: 46130 | J35: 0880603710 | K35: 16.316167 | L35: 103.60189 | M35: OSM Nominatim — ระดับตำบล
A36: 35 | B36: หจก. โรงสีไฟกาฬสินธุ์รุ่งเรือง 3 | C36: โรงสีขนาดใหญ่ | D36: 500 | E36: กาฬสินธุ์ | F36: กมลาไสย | G36: กมลาไสย | H36: เลขที่ 77 หมู่ 5 ถนน กาฬสินธุ์ - ร้อยเอ็ด ตำบลกมลาไสย อำเภอกมลาไสย จังหวัดกาฬสินธุ์ 46130 | I36: 46130 | J36: 043-899225 | K36: 16.316167 | L36: 103.60189 | M36: OSM Nominatim — ระดับตำบล
A37: 36 | B37: ห้างหุ้นส่วนจำกัด เทพพิชิต 2020 | C37: โรงสีขนาดเล็ก | D37: 15 | E37: กาฬสินธุ์ | F37: กมลาไสย | G37: กมลาไสย | H37: เลขที่ 112 หมู่ 10 ตำบลกมลาไสย อำเภอกมลาไสย จังหวัดกาฬสินธุ์ 46130 | I37: 46130 | J37: 0918675059 | K37: 16.316167 | L37: 103.60189 | M37: OSM Nominatim — ระดับตำบล
A38: 37 | B38: วิสาหกิจชุมชนเกษตรอินทรีย์นาภูตำบลหนองห้าง | C38: โรงสีขนาดเล็ก | D38: 8 | E38: กาฬสินธุ์ | F38: กุฉินารายณ์ | G38: หนองห้าง | H38: เลขที่ 155 หมู่ 9 ถนน - ตำบลหนองห้าง อำเภอกุฉินารายณ์ จังหวัดกาฬสินธุ์ 46110 | I38: 46110 | J38: 0870903859 | K38: 16.535108 | L38: 104.05394 | M38: OSM Nominatim — ระดับอำเภอ (ตำบลหาไม่เจอ)
A39: 38 | B39: โรงสีข้าวไทรงามไรซ์อินเตอร์เทรด | C39: โรงสีขนาดเล็ก | D39: 30 | E39: กาฬสินธุ์ | F39: คำม่วง | G39: ทุ่งคลอง | H39: เลขที่ 115 หมู่ 9 ถนน คำม่วง-ทุ่งคลอง ตำบลทุ่งคลอง อำเภอคำม่วง จังหวัดกาฬสินธุ์ 46180 | I39: 46180 | J39: 043-879227 | K39: 16.933201 | L39: 103.67141 | M39: OSM Nominatim — ระดับอำเภอ (ตำบลหาไม่เจอ)
A40: 39 | B40: บริษัท โรงสีข้าวทองสมบูรณ์พืชผลไรซ์ จำกัด | C40: โรงสีขนาดกลาง | D40: 200 | E40: กาฬสินธุ์ | F40: ฆ้องชัย | G40: เหล่ากลาง | H40: เลขที่ 256 หมู่ 1 ตำบลเหล่ากลาง อำเภอฆ้องชัย จังหวัดกาฬสินธุ์ 46130 | I40: 46130 | J40: 0892056672 | K40: 16.262835 | L40: 103.47331 | M40: OSM Nominatim — ระดับอำเภอ (ตำบลหาไม่เจอ)
...

Sheet ระยะห่างโรงสี-โรงสี
A1: จังหวัด | B1: ชื่อโรงสี | C1: อำเภอ | D1: ตำบล | E1: โรงสีที่ใช้พิกัดเดียวกัน (แห่ง) | F1: โรงสีใกล้สุดที่พิกัดต่างกัน | G1: ระยะห่าง (กม.) ⭐ใช้ค่านี้ | H1: โรงสีใกล้สุด (นับทุกแห่ง) | I1: ระยะห่าง (กม.) | J1: ความละเอียดพิกัด
A2: กรุงเทพมหานคร | B2: บริษัท ข้าว ซี.พี. จำกัด | C2: บางรัก | D2: สีลม | E2: 2 | F2: บริษัท ไร้ซ์แลนด์ อินเตอร์เนชั่นแนล จำกัด | G2: 0.43 | H2: บริษัท ข้าว ซี.พี. จำกัด | I2: 0 | J2: ตำบล
A3: กรุงเทพมหานคร | B3: บริษัท ข้าว ซี.พี. จำกัด | C3: บางรัก | D3: สีลม | E3: 2 | F3: บริษัท ไร้ซ์แลนด์ อินเตอร์เนชั่นแนล จำกัด | G3: 0.43 | H3: บริษัท ข้าว ซี.พี. จำกัด | I3: 0 | J3: ตำบล
A4: กรุงเทพมหานคร | B4: บริษัท ไร้ซ์แลนด์ อินเตอร์เนชั่นแนล จำกัด | C4: บางรัก | D4: สุริยวงศ์ | E4: 0 | F4: บริษัท ข้าว ซี.พี. จำกัด | G4: 0.43 | H4: บริษัท ข้าว ซี.พี. จำกัด | I4: 0.43 | J4: ตำบล
A5: กรุงเทพมหานคร | B5: บริษัท ข้าว ซี.พี. จำกัด | C5: บางรัก | D5: สีลม | E5: 2 | F5: บริษัท ไร้ซ์แลนด์ อินเตอร์เนชั่นแนล จำกัด | G5: 0.43 | H5: บริษัท ข้าว ซี.พี. จำกัด | I5: 0 | J5: ตำบล
A6: กรุงเทพมหานคร | B6: บริษัท เจริญโภคภัณฑ์โปรดิ๊วส จำกัด | C6: สาทร | D6: ทุ่งวัดดอน | E6: 0 | F6: บริษัท ไร้ซ์แลนด์ อินเตอร์เนชั่นแนล จำกัด | G6: 1.58 | H6: บริษัท ไร้ซ์แลนด์ อินเตอร์เนชั่นแนล จำกัด | I6: 1.58 | J6: ตำบล
A7: กรุงเทพมหานคร | B7: บริษัท เม้งไต๋ ไรซ์ จำกัด | C7: ห้วยขวาง | D7: ห้วยขวาง | E7: 1 | F7: บริษัท เหล่าบัณฑิต ไรซ์ จำกัด | G7: 1.93 | H7: บริษัท เอ็มที เซ็นเตอร์เทรด จำกัด | I7: 0 | J7: ตำบล
A8: กรุงเทพมหานคร | B8: บริษัท เหล่าบัณฑิต ไรซ์ จำกัด | C8: ห้วยขวาง | D8: สามเสนนอก | E8: 0 | F8: บริษัท เม้งไต๋ ไรซ์ จำกัด | G8: 1.93 | H8: บริษัท เม้งไต๋ ไรซ์ จำกัด | I8: 1.93 | J8: ตำบล
A9: กรุงเทพมหานคร | B9: บริษัท เอ็มที เซ็นเตอร์เทรด จำกัด | C9: ห้วยขวาง | D9: ห้วยขวาง | E9: 1 | F9: บริษัท เหล่าบัณฑิต ไรซ์ จำกัด | G9: 1.93 | H9: บริษัท เม้งไต๋ ไรซ์ จำกัด | I9: 0 | J9: ตำบล
A10: กรุงเทพมหานคร | B10: บริษัท บีบีพี โปรดิวซ์ จำกัด | C10: บางคอแหลม | D10: บางโคล่ | E10: 0 | F10: บริษัท เจริญโภคภัณฑ์โปรดิ๊วส จำกัด | G10: 2.36 | H10: บริษัท เจริญโภคภัณฑ์โปรดิ๊วส จำกัด | I10: 2.36 | J10: ตำบล
A11: กรุงเทพมหานคร | B11: บริษัท ชัยประสิทธิ์พืชผล จำกัด | C11: ป้อมปราบศัตรูพ่าย | D11: วัดเทพศิรินทร์ | E11: 0 | F11: บริษัท ไร้ซ์แลนด์ อินเตอร์เนชั่นแนล จำกัด | G11: 2.52 | H11: บริษัท ไร้ซ์แลนด์ อินเตอร์เนชั่นแนล จำกัด | I11: 2.52 | J11: ตำบล
A12: กรุงเทพมหานคร | B12: บริษัท บางซื่อโรงสีไฟเจียเม้ง จำกัด | C12: บางซื่อ | D12: บางซื่อ | E12: 3 | F12: บริษัท เม้งไต๋ ไรซ์ จำกัด | G12: 5.3 | H12: บริษัท บางซื่อโรงสีไฟเจียเม้ง จำกัด | I12: 0 | J12: ตำบล
A13: กรุงเทพมหานคร | B13: บริษัท บางซื่อโรงสีไฟเจียเม้ง จำกัด | C13: บางซื่อ | D13: บางซื่อ | E13: 3 | F13: บริษัท เม้งไต๋ ไรซ์ จำกัด | G13: 5.3 | H13: บริษัท บางซื่อโรงสีไฟเจียเม้ง จำกัด | I13: 0 | J13: ตำบล
... A94: ขอนแก่น | B94: บริษัท โรงสีมีชัย จำกัด | C94: ชุมแพ | D94: หนองไผ่ | E94: 2 | F94: หจก.โรงสีน้ำพองไฮ้พืชพล (2008) | G94: 69.4 | H94: บริษัท โรงสีไฟสหชัยชุมแพ จำกัด | I94: 0 | J94: ตำบล
A95: จันทบุรี | B95: ปานบุญ | C95: เมืองจันทบุรี | D95: หนองบัว | E95: 0 | J95: ตำบล
A96: ฉะเชิงเทรา | B96: บริษัท ใจข้าว คอร์ปอเรชั่น จำกัด | C96: บางน้ำเปรี้ยว | D96: บางขนาก | E96: 3 | F96: บริษัท เกรียงชัยโกลเด้นไรซ์ จำกัด | G96: 1.82 | H96: บริษัท ยี่สิบไพบูลย์ ไรซ์ อินเตอร์เทรด 2009 จำกัด | I96: 0 | J96: อำเภอ
A97: ฉะเชิงเทรา | B97: บริษัท เกรียงชัยโกลเด้นไรซ์ จำกัด | C97: บางน้ำเปรี้ยว | D97: บางน้ำเปรี้ยว | E97: 1 | F97: บริษัท ใจข้าว คอร์ปอเรชั่น จำกัด | G97: 1.82 | H97: บริษัท โรงสีศิริพร จำกัด | I97: 0 | J97: ตำบล
A98: ฉะเชิงเทรา | B98: บริษัท ยี่สิบไพบูลย์ ไรซ์ อินเตอร์เทรด 2009 จำกัด | C98: บางน้ำเปรี้ยว | D98: สิงโตทอง | E98: 3 | F98: บริษัท เกรียงชัยโกลเด้นไรซ์ จำกัด | G98: 1.82 | H98: บริษัท ใจข้าว คอร์ปอเรชั่น จำกัด | I98: 0 | J98: อำเภอ
A99: ฉะเชิงเทรา | B99: บริษัท โรงสีศิริพร จำกัด | C99: บางน้ำเปรี้ยว | D99: หมอนทอง | E99: 1 | F99: บริษัท ใจข้าว คอร์ปอเรชั่น จำกัด | G99: 1.82 | H99: บริษัท เกรียงชัยโกลเด้นไรซ์ จำกัด | I99: 0 | J99: ตำบล
A100: ฉะเชิงเทรา | B100: บริษัท โรงสีเตียหลีฮง จำกัด | C100: บางน้ำเปรี้ยว | D100: โพรงอากาศ | E100: 3 | F100: บริษัท เกรียงชัยโกลเด้นไรซ์ จำกัด | G100: 1.82 | H100: บริษัท ใจข้าว คอร์ปอเรชั่น จำกัด | I100: 0 | J100: อำเภอ
A101: ฉะเชิงเทรา | B101: บริษัท ชัยวัฒนาไรซ์มิลล์ จำกัด | C101: บางน้ำเปรี้ยว | D101: ดอนฉิมพลี | E101: 3 | F101: บริษัท เกรียงชัยโกลเด้นไรซ์ จำกัด | G101: 1.82 | H101: บริษัท ใจข้าว คอร์ปอเรชั่น จำกัด | I101: 0 | J101: อำเภอ
A102: ฉะเชิงเทรา | B102: โรงสีโชคโกมล | C102: พนมสารคาม | D102: เมืองเก่า | E102: 0 | F102: บริษัท ธนศักดิ์ไพบูลย์ พืชผล จำกัด | G102: 8.43 | H102: บริษัท ธนศักดิ์ไพบูลย์ พืชผล จำกัด | I102: 8.43 | J102: อำเภอ
A103: ฉะเชิงเทรา | B103: บริษัท ธนศักดิ์ไพบูลย์ พืชผล จำกัด | C103: ราชสาส์น | D103: เมืองใหม่ | E103: 1 | F103: โรงสีโชคโกมล | G103: 8.43 | H103: บริษัท ราชสาส์น ไรซ์ อินเตอร์เทรด จำกัด | I103: 0 | J103: อำเภอ
A104: ฉะเชิงเทรา | B104: บริษัท ราชสาส์น ไรซ์ อินเตอร์เทรด จำกัด | C104: ราชสาส์น | D104: ดงน้อย | E104: 1 | F104: โรงสีโชคโกมล | G104: 8.43 | H104: บริษัท ธนศักดิ์ไพบูลย์ พืชผล จำกัด | I104: 0 | J104: อำเภอ
A105: ฉะเชิงเทรา | B105: บริษัท ช.สิริยี่สิบไพบูลย์ จำกัด | C105: บางน้ำเปรี้ยว | D105: ดอนเกาะกา | E105: 2 | F105: บริษัท ใจข้าว คอร์ปอเรชั่น จำกัด | G105: 12.85 | H105: บริษัท สุขนิรันดร์ไรซ์มิลล์ จำกัด | I105: 0 | J105: ตำบล
A106: ฉะเชิงเทรา | B106: บริษัท สุขนิรันดร์ไรซ์มิลล์ จำกัด | C106: บางน้ำเปรี้ยว | D106: ศาลาแดง | E106: 2 | F106: บริษัท ใจข้าว คอร์ปอเรชั่น จำกัด | G106: 12.85 | H106: บริษัท ช.สิริยี่สิบไพบูลย์ จำกัด | I106: 0 | J106: ตำบล
A107: ฉะเชิงเทรา | B107: บจก.ดี.เอส.เค.อินเตอร์เทรด | C107: บางน้ำเปรี้ยว | D107: ดอนเกาะกา | E107: 2 | F107: บริษัท ใจข้าว คอร์ปอเรชั่น จำกัด | G107: 12.85 | H107: บริษัท ช.สิริยี่สิบไพบูลย์ จำกัด | I107: 0 | J107: ตำบล
... A167: ชัยภูมิ | B167: โรงสีข้าวนิวัฒน์ฟาร์ม | C167: คอนสวรรค์ | D167: บ้านโสก | E167: 0 | F167: บริษัท เลียงเจริญการเกษตร จำกัด | G167: 24.49 | H167: บริษัท เลียงเจริญการเกษตร จำกัด | I167: 24.49 | J167: อำเภอ
A168: ตราด | B168: โรงสีประเสริฐทรัพย์ 2 | C168: เมืองตราด | D168: เนินทราย | E168: 1 | H168: วิสาหกิจชุมชนโรงสีข้าวชาวนาตราด | I168: 0 | J168: ตำบล
A169: ตราด | B169: วิสาหกิจชุมชนโรงสีข้าวชาวนาตราด | C169: เมืองตราด | D169: เนินทราย | E169: 1 | H169: โรงสีประเสริฐทรัพย์ 2 | I169: 0 | J169: ตำบล
A170: ตาก | B170: โรงสีสุพลธัญญกิจ | C170: แม่สอด | D170: พระธาตุผาแดง | E170: 0 | F170: สหกรณ์การเกษตรบ้านตาก จำกัด | G170: 78.63 | H170: สหกรณ์การเกษตรบ้านตาก จำกัด | I170: 78.63 | J170: ตำบล
A171: ตาก | B171: สหกรณ์การเกษตรบ้านตาก จำกัด | C171: บ้านตาก | D171: เกาะตะเภา | E171: 0 | F171: โรงสีสุพลธัญญกิจ | G171: 78.63 | H171: โรงสีสุพลธัญญกิจ | I171: 78.63 | J171: อำเภอ
A172: นครนายก | B172: โรงสีสินอุดม | C172: องครักษ์ | D172: พระอาจารย์ | E172: 4 | H172: บริษัทพิมานไรซ์ จำกัด | I172: 0 | J172: อำเภอ
A173: นครนายก | B173: บริษัทพิมานไรซ์ จำกัด | C173: องครักษ์ | D173: ชุมพล | E173: 4 | H173: โรงสีสินอุดม | I173: 0 | J173: อำเภอ
A174: นครนายก | B174: บริษัทโรงสีบุญทวีทรัพย์(กำนันชา) จำกัด | C174: องครักษ์ | D174: พระอาจารย์ | E174: 4 | H174: โรงสีสินอุดม | I174: 0 | J174: อำเภอ
A175: นครนายก | B175: บริษัท โรงสีเก่งการ 22 จำกัด | C175: องครักษ์ | D175: บางลูกเสือ | E175: 4 | H175: โรงสีสินอุดม | I175: 0 | J175: อำเภอ
A176: นครนายก | B176: บริษัท สินอุดมไรซ์มิลล์ จำกัด | C176: องครักษ์ | D176: พระอาจารย์ | E176: 4 | H176: โรงสีสินอุดม | I176: 0 | J176: อำเภอ
A177: นครปฐม | B177: ห้างหุ้นส่วนจำกัด โรงสีแต้พานิชเจริญ | C177: ดอนตูม | D177: สามง่าม | E177: 0 | F177: จิ้งเฮงล้ง | G177: 1.99 | H177: จิ้งเฮงล้ง | I177: 1.99 | J177: ตำบล
A178: นครปฐม | B178: จิ้งเฮงล้ง | C178: ดอนตูม | D178: ห้วยด้วน | E178: 0 | F178: ห้างหุ้นส่วนจำกัด โรงสีแต้พานิชเจริญ | G178: 1.99 | H178: ห้างหุ้นส่วนจำกัด โรงสีแต้พานิชเจริญ | I178: 1.99 | J178: อำเภอ
A179: นครปฐม | B179: บริษัท โรงสีเกษตรธรรม จำกัด | C179: เมืองนครปฐม | D179: วังตะกู | E179: 2 | F179: สหกรณ์การเกษตรเพื่อการตลาดลูกค้าธ.ก.ส.นครปฐม จำกัด | G179: 2.8 | H179: บริษัท โรงสีทรัพย์สมบัติ จำกัด | I179: 0 | J179: ตำบล
...

Sheet ระยะห่างจากตัวเมือง
A1: จังหวัด | B1: ชื่อโรงสี | C1: อำเภอ | D1: ตำบล | E1: ระยะห่างจากตัวเมือง (กม.) | F1: กำลังการผลิต (ตัน/วัน) | G1: ประเภท
A2: กรุงเทพมหานคร | B2: บริษัท ชัยประสิทธิ์พืชผล จำกัด | C2: ป้อมปราบศัตรูพ่าย | D2: วัดเทพศิรินทร์ | E2: 18.34 | F2: 90 | G2: โรงสีขนาดกลาง
A3: กรุงเทพมหานคร | B3: บริษัท บางซื่อโรงสีไฟเจียเม้ง จำกัด | C3: บางซื่อ | D3: บางซื่อ | E3: 19.74 | F3: 436 | G3: โรงสีขนาดใหญ่
A4: กรุงเทพมหานคร | B4: บริษัท บางซื่อโรงสีไฟเจียเม้ง จำกัด | C4: บางซื่อ | D4: บางซื่อ | E4: 19.74 | F4: 400 | G4: โรงสีขนาดใหญ่
A5: กรุงเทพมหานคร | B5: บริษัท บางซื่อโรงสีไฟเจียเม้ง จำกัด | C5: บางซื่อ | D5: บางซื่อ | E5: 19.74 | F5: 800 | G5: โรงสีขนาดใหญ่
A6: กรุงเทพมหานคร | B6: บริษัท บางซื่อโรงสีไฟเจียเม้ง จำกัด | C6: บางซื่อ | D6: บางซื่อ | E6: 19.74 | F6: 720 | G6: โรงสีขนาดใหญ่
A7: กรุงเทพมหานคร | B7: บริษัท ไร้ซ์แลนด์ อินเตอร์เนชั่นแนล จำกัด | C7: บางรัก | D7: สุริยวงศ์ | E7: 20.19 | F7: 500 | G7: โรงสีขนาดใหญ่
A8: กรุงเทพมหานคร | B8: บริษัท ข้าว ซี.พี. จำกัด | C8: บางรัก | D8: สีลม | E8: 20.59 | F8: 400 | G8: โรงสีขนาดใหญ่
A9: กรุงเทพมหานคร | B9: บริษัท ข้าว ซี.พี. จำกัด | C9: บางรัก | D9: สีลม | E9: 20.59 | F9: 400 | G9: โรงสีขนาดใหญ่
A10: กรุงเทพมหานคร | B10: บริษัท ข้าว ซี.พี. จำกัด | C10: บางรัก | D10: สีลม | E10: 20.59 | F10: 96 | G10: โรงสีขนาดกลาง
A11: กรุงเทพมหานคร | B11: บริษัท เจริญโภคภัณฑ์โปรดิ๊วส จำกัด | C11: สาทร | D11: ทุ่งวัดดอน | E11: 20.64 | F11: 1000 | G11: โรงสีขนาดใหญ่
A12: กรุงเทพมหานคร | B12: บริษัท บีบีพี โปรดิวซ์ จำกัด | C12: บางคอแหลม | D12: บางโคล่ | E12: 21.16 | F12: 200 | G12: โรงสีขนาดกลาง
A13: กรุงเทพมหานคร | B13: บริษัท เม้งไต๋ ไรซ์ จำกัด | C13: ห้วยขวาง | D13: ห้วยขวาง | E13: 23.9 | F13: 1500 | G13: โรงสีขนาดใหญ่
... A904: แพร่ | B904: โรงสีข้าวคนอง | C904: เมืองแพร่ | D904: กาญจนา | E904: 50.17 | F904: 20 | G904: โรงสีขนาดเล็ก

Sheet สรุปรายจังหวัด
A1: จังหวัด | B1: จำนวนโรงสี | C1: จำนวนจุดพิกัดที่ต่างกัน | D1: กำลังผลิตรวม (ตัน/วัน) | E1: ระยะเฉลี่ยถึงโรงสีที่พิกัดต่างกัน (กม.) | F1: ใกล้สุด (กม.) | G1: ไกลสุด (กม.) | H1: ระยะจากตัวเมืองเฉลี่ย (กม.) | I1: ไกลจากเมืองสุด (กม.) | J1: % พิกัดระดับตำบล
A2: กรุงเทพมหานคร | B2: 19 | C2: 12 | D2: 11032 | E2: 4.15 | F2: 0.43 | G2: 11.55 | H2: 29.14 | I2: 62.31 | J2: 100
A3: กาญจนบุรี | B3: 14 | C3: 14 | D3: 2867 | E3: 11.34 | F3: 3.23 | G3: 26.81 | H3: 23.34 | I3: 67.15 | J3: 50
A4: กาฬสินธุ์ | B4: 17 | C4: 14 | D4: 3058 | E4: 11.58 | F4: 5.84 | G4: 25.43 | H4: 27.36 | I4: 63.32 | J4: 76
A5: กำแพงเพชร | B5: 25 | C5: 15 | D5: 13258 | E5: 14.7 | F5: 10.47 | G5: 20.76 | H5: 50.58 | I5: 88.24 | J5: 100
A6: ขอนแก่น | B6: 18 | C6: 15 | D6: 3700 | E6: 18.95 | F6: 3.94 | G6: 69.4 | H6: 49.89 | I6: 78.86 | J6: 89
A7: จันทบุรี | B7: 1 | C7: 1 | D7: 6 | H7: 7.65 | I7: 7.65 | J7: 100
A8: ฉะเชิงเทรา | B8: 23 | C8: 18 | D8: 10825 | E8: 11.56 | F8: 1.82 | G8: 34.48 | H8: 21.42 | I8: 61.43 | J8: 43
A9: ชลบุรี | B9: 4 | C9: 4 | D9: 185 | E9: 19.21 | F9: 18.88 | G9: 19.55 | H9: 24.39 | I9: 30.53 | J9: 25
A10: ชัยนาท | B10: 36 | C10: 21 | D10: 17878 | E10: 7.29 | F10: 1.13 | G10: 18.01 | H10: 14.94 | I10: 39.15 | J10: 53
A11: ชัยภูมิ | B11: 9 | C11: 7 | D11: 1092 | E11: 19.97 | F11: 9.5 | G11: 24.49 | H11: 18.64 | I11: 45.92 | J11: 11
A12: ตราด | B12: 2 | C12: 1 | D12: 36 | H12: 1.1 | I12: 1.1 | J12: 100
A13: ตาก | B13: 2 | C13: 2 | D13: 85 | E13: 78.63 | F13: 78.63 | G13: 78.63 | H13: 45.45 | I13: 60.14 | J13: 50
A14: นครนายก | B14: 5 | C14: 3 | D14: 2098 | H14: 10.68 | I14: 10.68 | J14: 0
A15: นครปฐม | B15: 38 | C15: 26 | D15: 8724 | E15: 7.54 | F15: 1.99 | G15: 15.67 | H15: 22.23 | I15: 37.36 | J15: 26
A16: นครพนม | B16: 7 | C16: 7 | D16: 1547 | E16: 21.6 | F16: 18.32 | G16: 32.84 | H16: 39.35 | I16: 64.27 | J16: 57
A17: นครราชสีมา | B17: 32 | C17: 26 | D17: 8117 | E17: 9.66 | F17: 2.2 | G17: 32.26 | H17: 36.26 | I17: 93.38 | J17: 78
A18: นครศรีธรรมราช | B18: 22 | C18: 14 | D18: 1494 | E18: 10.02 | F18: 9.39 | G18: 14.32 | H18: 37.75 | I18: 54.04 | J18: 27
A19: นครสวรรค์ | B19: 55 | C19: 34 | D19: 22242.5 | E19: 10.8 | F19: 2.48 | G19: 21.59 | H19: 45.93 | I19: 80.44 | J19: 36
A20: นนทบุรี | B20: 8 | C20: 5 | D20: 6523.4 | E20: 11.33 | F20: 9.54 | G20: 13.67 | H20: 21 | I20: 34.84 | J20: 100
A21: น่าน | B21: 1 | C21: 1 | D21: 90 | H21: 20.01 | I21: 20.01 | J21: 100
A22: บุรีรัมย์ | B22: 19 | C22: 18 | D22: 3201.8 | E22: 14.72 | F22: 5.71 | G22: 42.18 | H22: 33.15 | I22: 77.72 | J22: 63
A23: ปทุมธานี | B23: 9 | C23: 7 | D23: 2137.4 | E23: 6.98 | F23: 3.44 | G23: 15.11 | H23: 17.77 | I23: 26.97 | J23: 100
A24: ประจวบคีรีขันธ์ | B24: 2 | C24: 2 | D24: 497 | E24: 55.85 | F24: 55.85 | G24: 55.85 | H24: 39.52 | I24: 66.48 | J24: 50
A25: ปราจีนบุรี | B25: 10 | C25: 9 | D25: 1513 | E25: 15.14 | F25: 0.5 | G25: 23.77 | H25: 23.94 | I25: 36.96 | J25: 50
A26: พระนครศรีอยุธยา | B26: 20 | C26: 18 | D26: 8352 | E26: 7.62 | F26: 2.25 | G26: 20.01 | H26: 28.77 | I26: 40.16 | J26: 100
A27: พะเยา | B27: 16 | C27: 11 | D27: 2090 | E27: 12.3 | F27: 4.21 | G27: 31.04 | H27: 47.13 | I27: 68.49 | J27: 50
A28: พัทลุง | B28: 8 | C28: 5 | D28: 280 | E28: 3.82 | F28: 0.12 | G28: 13.72 | H28: 4.26 | I28: 17.04 | J28: 50
A29: พิจิตร | B29: 24 | C29: 19 | D29: 8965 | E29: 8.83 | F29: 4.72 | G29: 21.11 | H29: 35.08 | I29: 51.68 | J29: 54
A30: พิษณุโลก | B30: 22 | C30: 16 | D30: 9760 | E30: 13.36 | F30: 3.74 | G30: 27.94 | H30: 20.74 | I30: 37.09 | J30: 36
A31: มหาสารคาม | B31: 21 | C31: 13 | D31: 4549 | E31: 14.46 | F31: 10.84 | G31: 19.74 | H31: 27.57 | I31: 64.03 | J31: 52
A32: มุกดาหาร | B32: 5 | C32: 3 | D32: 795 | E32: 9.5 | F32: 5.29 | G32: 26.35 | H32: 17.98 | I32: 37.46 | J32: 80
A33: ยโสธร | B33: 18 | C33: 14 | D33: 3555 | E33: 6.9 | F33: 3.33 | G33: 19.41 | H33: 28.77 | I33: 64.33 | J33: 72
... A61: แพร่ | B61: 2 | C61: 2 | D61: 420 | E61: 15.65 | F61: 15.65 | G61: 15.65 | H61: 44.12 | I61: 50.17 | J61: 50

Sheet วิธีการ & แหล่งข้อมูล
A1: หัวข้อ | B1: รายละเอียด
A2: แหล่งข้อมูลโรงสี | B2: กรมการค้าภายใน (DIT) — รายชื่อผู้ประกอบการโรงสีข้าว https://www.dit.go.th/th/find-entrepreneur/rice/ (ไฟล์ export 23 เม.ย. 2569)
A3: จำนวนโรงสี | B3: 903 แห่ง ใน 60 จังหวัด
A4: ที่มาของพิกัด (สำคัญ) | B4: DIT ไม่ได้ให้ lat/lon — เราแปลงที่อยู่ระดับ ตำบล/อำเภอ/จังหวัด เป็นพิกัดด้วย OpenStreetMap Nominatim (https://nominatim.openstreetmap.org)
A5: ⚠️ ข้อจำกัดความแม่นยำ | B5: พิกัดเป็นระดับ 'ตำบล' ไม่ใช่ตำแหน่งโรงสีจริง คลาดเคลื่อนได้ราว 2-8 กม. ใช้ดูภาพรวมการกระจายตัว/เปรียบเทียบเชิงพื้นที่ได้ แต่ไม่ควรใช้วางแผนขนส่งที่ต้องการความแม่นยำสูง
A6: ⚠️ โรงสีในตำบลเดียวกัน | B6: จะได้พิกัดเดียวกัน ทำให้ 'ระยะห่าง = 0' ทั้งที่จริงอาจห่างกันหลายกิโลเมตร (เกิดกับ ~62% ของโรงสี) ดูคอลัมน์ 'จำนวนโรงสีในตำบลเดียวกัน' ประกอบเสมอ
A7: ⭐ ควรใช้คอลัมน์ไหน | B7: ในชีต 'ระยะห่างโรงสี-โรงสี' ให้ใช้ 'ระยะห่างถึงโรงสีใกล้สุดที่พิกัดต่างกัน' เป็นหลัก เพราะเป็นค่าที่วัดได้จริงจากความละเอียดของข้อมูล ส่วนคอลัมน์ 'นับทุกแห่ง' จะเป็น 0 จำนวนมาก ซึ่งแปลว่าพิกัดชนกัน ไม่ได้แปลว่าโรงสีตั้งอยู่ที่เดียวกันจริง
A8: ความละเอียดพิกัดแต่ละแถว | B8: ดูคอลัมน์ 'ความละเอียดพิกัด' — 'ตำบล' แม่นกว่า (~2-8 กม.) · 'อำเภอ' หยาบกว่า (~5-20 กม.) เพราะ Nominatim หาระดับตำบลไม่เจอจึงถอยมาใช้จุดกึ่งกลางอำเภอแทน
A9: การตรวจสอบความถูกต้อง | B9: ทุกพิกัดถูกตรวจว่าตกอยู่ในกรอบเขตจังหวัดที่ถูกต้องจริง (province bbox validation) พบและแก้ไขพิกัดที่ Nominatim จับผิดจังหวัด เช่น 'ศาลากลางจังหวัดลำพูน' ที่เคยได้พิกัดในกรุงเทพฯ
A10: วิธีคำนวณระยะทาง | B10: Haversine (ระยะทางเส้นตรงบนผิวโลก, รัศมีโลก 6,371 กม.) — ไม่ใช่ระยะทางตามถนนจริง
A11: ตัวเมืองจังหวัด | B11: พิกัดศาลากลางจังหวัด (fallback: อำเภอเมือง) จาก Nominatim
A12: โรงสีที่ใกล้ที่สุด | B12: คำนวณเฉพาะโรงสีภายในจังหวัดเดียวกันเท่านั้น (ไม่ข้ามจังหวัด)
A13: จัดทำเมื่อ | B13: 2026-07-30 11:13

Sheet แผนที่โรงสี
A1: แผนที่การกระจายตัวของโรงสีข้าว (Scatter Map จากพิกัด Lat/Long)
A2: แกน X = Longitude, แกน Y = Latitude — แต่ละจุดคือโรงสี 1 แห่ง แยกสีตามขนาดโรงสี
A4: โรงสีขนาดใหญ่ | C4: โรงสีขนาดกลาง | E4: โรงสีขนาดเล็ก | H4: ตารางสรุปรายจังหวัด (จุดศูนย์กลางเชิงเรขาคณิต)
A5: Longitude | B5: Latitude | C5: Longitude | D5: Latitude | E5: Longitude | F5: Latitude | H5: จังหวัด | I5: Longitude เชลี่ย | J5: Latitude เชลี่ย | K5: จำนวนโรงสี | L5: กำลังผลิตรวม (ตัน/วัน)
A6: {=IFERROR(_xlfn._xlws.FILTER(รายชื่อโรงสี!$L$2:$L$904,รายชื่อโรงสี!$C$2:$C$904=$A$4),"")} -> 100.53744 | B6: {=IFERROR(_xlfn._xlws.FILTER(รายชื่อโรงสี!$K$2:$K$904,รายชื่อโรงสี!$C$2:$C$904=$A$4),"")} -> 13.809713 | C6: {=IFERROR(_xlfn._xlws.FILTER(รายชื่อโรงสี!$L$2:$L$904,รายชื่อโรงสี!$C$2:$C$904=$C$4),"")} -> 100.51401 | D6: {=IFERROR(_xlfn._xlws.FILTER(รายชื่อโรงสี!$K$2:$K$904,รายชื่อโรงสี!$C$2:$C$904=$C$4),"")} -> 13.692452 | E6: {=IFERROR(_xlfn._xlws.FILTER(รายชื่อโรงสี!$L$2:$L$904,รายชื่อโรงสี!$C$2:$C$904=$E$4),"")} -> 99.802476 | F6: {=IFERROR(_xlfn._xlws.FILTER(รายชื่อโรงสี!$K$2:$K$904,รายชื่อโรงสี!$C$2:$C$904=$E$4),"")} -> 13.886985 | H6: =สรุปรายจังหวัด!A2 -> กรุงเทพมหานคร | I6: =AVERAGEIFS(รายชื่อโรงสี!$L$2:$L$904,รายชื่อโรงสี!$E$2:$E$904,$H6) -> 100.61647 | J6: =AVERAGEIFS(รายชื่อโรงสี!$K$2:$K$904,รายชื่อโรงสี!$E$2:$E$904,$H6) -> 13.768286 | K6: =สรุปรายจังหวัด!B2 -> 19 | L6: =สรุปรายจังหวัด!D2 -> 11032
A7: 100.53744 | B7: 13.809713 | C7: 100.52813 | D7: 13.726234 | E7: 99.821101 | F7: 14.254942 | H7: =สรุปรายจังหวัด!A3 -> กาญจนบุรี | I7: =AVERAGEIFS(รายชื่อโรงสี!$L$2:$L$904,รายชื่อโรงสี!$E$2:$E$904,$H7) -> 99.669551 | J7: =AVERAGEIFS(รายชื่อโรงสี!$K$2:$K$904,รายชื่อโรงสี!$E$2:$E$904,$H7) -> 14.098836 | K7: =สรุปรายจังหวัด!B3 -> 14 | L7: =สรุปรายจังหวัด!D3 -> 2867
A8: 100.53744 | B8: 13.809713 | C8: 100.51433 | D8: 13.746956 | E8: 99.676776 | F8: 14.147976 | H8: =สรุปรายจังหวัด!A4 -> กาฬสินธุ์ | I8: =AVERAGEIFS(รายชื่อโรงสี!$L$2:$L$904,รายชื่อโรงสี!$E$2:$E$904,$H8) -> 103.62147 | J8: =AVERAGEIFS(รายชื่อโรงสี!$K$2:$K$904,รายชื่อโรงสี!$E$2:$E$904,$H8) -> 16.494576 | K8: =สรุปรายจังหวัด!B4 -> 17 | L8: =สรุปรายจังหวัด!D4 -> 3058
A9: 100.53744 | B9: 13.809713 | C9: 100.8285 | D9: 13.784278 | E9: 99.691822 | F9: 14.591952 | H9: =สรุปรายจังหวัด!A5 -> กำแพงเพชร | I9: =AVERAGEIFS(รายชื่อโรงสี!$L$2:$L$904,รายชื่อโรงสี!$E$2:$E$904,$H9) -> 99.689787 | J9: =AVERAGEIFS(รายชื่อโรงสี!$K$2:$K$904,รายชื่อโรงสี!$E$2:$E$904,$H9) -> 16.276778 | K9: =สรุปรายจังหวัด!B5 -> 25 | L9: =สรุปรายจังหวัด!D5 -> 13258
A10: 100.52813 | B10: 13.726234 | C10: 99.643443 | D10: 13.930349 | E10: 103.60189 | F10: 16.316167 | H10: =สรุปรายจังหวัด!A6 -> ขอนแก่น | I10: =AVERAGEIFS(รายชื่อโรงสี!$L$2:$L$904,รายชื่อโรงสี!$E$2:$E$904,$H10) -> 102.66216 | J10: =AVERAGEIFS(รายชื่อโรงสี!$K$2:$K$904,รายชื่อโรงสี!$E$2:$E$904,$H10) -> 16.241168 | K10: =สรุปรายจังหวัด!B6 -> 18 | L10: =สรุปรายจังหวัด!D6 -> 3700
A11: 100.52813 | B11: 13.726234 | C11: 99.643443 | D11: 13.930349 | E11: 103.60189 | F11: 16.316167 | H11: =สรุปรายจังหวัด!A7 -> จันทบุรี | I11: =AVERAGEIFS(รายชื่อโรงสี!$L$2:$L$904,รายชื่อโรงสี!$E$2:$E$904,$H11) -> 102.11312 | J11: =AVERAGEIFS(รายชื่อโรงสี!$K$2:$K$904,รายชื่อโรงสี!$E$2:$E$904,$H11) -> 12.542394 | K11: =สรุปรายจังหวัด!B7 -> 1 | L11: =สรุปรายจังหวัด!D7 -> 6
A12: 100.52415 | B12: 13.726431 | C12: 99.643443 | D12: 13.930349 | E12: 104.05394 | F12: 16.535108 | H12: =สรุปรายจังหวัด!A8 -> ฉะเชิงเทรา | I12: =AVERAGEIFS(รายชื่อโรงสี!$L$2:$L$904,รายชื่อโรงสี!$E$2:$E$904,$H12) -> 101.09975 | J12: =AVERAGEIFS(รายชื่อโรงสี!$K$2:$K$904,รายชื่อโรงสี!$E$2:$E$904,$H12) -> 13.76831 | K12: =สรุปรายจังหวัด!B8 -> 23 | L12: =สรุปรายจังหวัด!D8 -> 10825
A13: 100.63771 | B13: 13.834879 | C13: 99.549034 | D13: 14.004146 | E13: 103.67141 | F13: 16.933201 | H13: =สรุปรายจังหวัด!A9 -> ชลบุรี | I13: =AVERAGEIFS(รายชื่อโรงสี!$L$2:$L$904,รายชื่อโรงสี!$E$2:$E$904,$H13) -> 101.13959 | J13: =AVERAGEIFS(รายชื่อโรงสี!$K$2:$K$904,รายชื่อโรงสี!$E$2:$E$904,$H13) -> 13.322687 | K13: =สรุปรายจังหวัด!B9 -> 4 | L13: =สรุปรายจังหวัด!D9 -> 185
A14: 100.83634 | B14: 13.732507 | C14: 99.621343 | D14: 14.02849 | E14: 104.02697 | F14: 16.762301 | H14: =สรุปรายจังหวัด!A10 -> ชัยนาท | I14: =AVERAGEIFS(รายชื่อโรงสี!$L$2:$L$904,รายชื่อโรงสี!$E$2:$E$904,$H14) -> 100.09439 | J14: =AVERAGEIFS(รายชื่อโรงสี!$K$2:$K$904,รายชื่อโรงสี!$E$2:$E$904,$H14) -> 15.14724 | K14: =สรุปรายจังหวัด!B10 -> 36 | L14: =สรุปรายจังหวัด!D10 -> 17878
A15: 100.52144 | B15: 13.712446 | C15: 99.688049 | D15: 14.350869 | E15: 103.82602 | F15: 16.607089 | H15: =สรุปรายจังหวัด!A11 -> ชัยภูมิ | I15: =AVERAGEIFS(รายชื่อโรงสี!$L$2:$L$904,รายชื่อโรงสี!$E$2:$E$904,$H15) -> 102.00666 | J15: =AVERAGEIFS(รายชื่อโรงสี!$K$2:$K$904,รายชื่อโรงสี!$E$2:$E$904,$H15) -> 15.862986 | K15: =สรุปรายจังหวัด!B11 -> 9 | L15: =สรุปรายจังหวัด!D11 -> 1092
A16: 100.93165 | B16: 13.811743 | C16: 99.447366 | D16: 14.060466 | E16: 103.52245 | F16: 16.408214 | H16: =สรุปรายจังหวัด!A12 -> ตราด | I16: =AVERAGEIFS(รายชื่อโรงสี!$L$2:$L$904,รายชื่อโรงสี!$E$2:$E$904,$H16) -> 102.51665 | J16: =AVERAGEIFS(รายชื่อโรงสี!$K$2:$K$904,รายชื่อโรงสี!$E$2:$E$904,$H16) -> 12.252989 | K16: =สรุปรายจังหวัด!B12 -> 2 | L16: =สรุปรายจังหวัด!D12 -> 36
A17: 100.93165 | B17: 13.811743 | C17: 103.47331 | D17: 16.262835 | E17: 103.64309 | F17: 16.398294 | H17: =สรุปรายจังหวัด!A13 -> ตาก | I17: =AVERAGEIFS(รายชื่อโรงสี!$L$2:$L$904,รายชื่อโรงสี!$E$2:$E$904,$H17) -> 98.874709 | J17: =AVERAGEIFS(รายชื่อโรงสี!$K$2:$K$904,รายชื่อโรงสี!$E$2:$E$904,$H17) -> 16.926197 | K17: =สรุปรายจังหวัด!B13 -> 2 | L17: =สรุปรายจังหวัด!D13 -> 85
A18: 100.5746 | B18: 13.778568 | C18: 103.3512 | D18: 16.441669 | E18: 99.803576 | F18: 15.990091 | H18: =สรุปรายจังหวัด!A14 -> นครนายก | I18: =AVERAGEIFS(รายชื่อโรงสี!$L$2:$L$904,รายชื่อโรงสี!$E$2:$E$904,$H18) -> 101.00829 | J18: =AVERAGEIFS(รายชื่อโรงสี!$K$2:$K$904,รายชื่อโรงสี!$E$2:$E$904,$H18) -> 14.102095 | K18: =สรุปรายจังหวัด!B14 -> 5 | L18: =สรุปรายจังหวัด!D14 -> 2098
... A65: 100.15289 | B65: 15.133286 | C65: 101.83919 | D65: 15.815544 | E65: 102.25042 | F65: 15.178176 | H65: =สรุปรายจังหวัด!A61 -> แพร่ | I65: =AVERAGEIFS(รายชื่อโรงสี!$L$2:$L$904,รายชื่อโรงสี!$E$2:$E$904,$H65) -> 100.23055 | J65: =AVERAGEIFS(รายชื่อโรงสี!$K$2:$K$904,รายชื่อโรงสี!$E$2:$E$904,$H65) -> 18.126645 | K65: =สรุปรายจังหวัด!B61 -> 2 | L65: =สรุปรายจังหวัด!D61 -> 420
A66: 100.21934 | B66: 15.180178 | C66: 102.00649 | D66: 15.935919 | E66: 100.16444 | F66: 8.346831
A67: 100.24519 | B67: 15.137736 | C67: 102.00649 | D67: 15.935919 | E67: 100.16444 | F67: 8.346831
A68: 100.24519 | B68: 15.137736 | C68: 102.2077 | D68: 16.133927 | E68: 99.929081 | F68: 8.325276
A69: 99.968366 | B69: 15.031587 | C69: 101.00829 | D69: 14.102095 | E69: 100.25515 | F69: 8.027677
A70: 99.968366 | B70: 15.031587 | C70: 101.00829 | D70: 14.102095 | E70: 100.30742 | F70: 8.094455
A71: 99.968366 | B71: 15.031587 | C71: 99.948 | D71: 14.019468 | E71: 100.25515 | F71: 8.027677
A72: 99.968366 | B72: 15.031587 | C72: 99.948 | D72: 14.019468 | E72: 100.25515 | F72: 8.027677
A73: 99.968366 | B73: 15.031587 | C73: 99.948 | D73: 14.019468 | E73: 100.30742 | F73: 8.094455
A74: 100.1249 | B74: 15.18517 | C74: 99.948 | D74: 14.019468 | E74: 100.30742 | F74: 8.094455
A75: 102.00649 | B75: 15.935919 | C75: 99.948 | D75: 14.019468 | E75: 100.25515 | F75: 8.027677
A76: 101.00829 | B76: 14.102095 | C76: 100.18178 | D76: 13.813721 | E76: 100.25515 | F76: 8.027677
A77: 101.00829 | B77: 14.102095 | C77: 100.19228 | D77: 14.034656 | E77: 100.16389 | F77: 8.119434
... A253: 100.17165 | B253: 18.169314 | C253: 104.03084 | D253: 15.057431 | E253: 99.970151 | F253: 12.953403
C254: 104.03084 | D254: 15.057431 | E254: 99.823859 | F254: 13.236268
C255: 104.16848 | D255: 15.110369 | E255: 99.825854 | F255: 13.238985
C256: 104.16848 | D256: 15.110369 | E256: 99.978704 | F256: 13.070831
C257: 104.16848 | D257: 15.110369 | E257: 100.81085 | F257: 16.100062
C258: 104.37348 | D258: 15.099398 | E258: 101.30548 | F258: 16.741979
C259: 104.35584 | D259: 14.98575 | E259: 100.28944 | F259: 18.083976
C260: 104.36303 | D260: 15.085549
C261: 104.29327 | D261: 15.073031
C262: 104.29327 | D262: 15.073031
...
